<?xml version="1.0" ?>
<!-- =================================================================================== -->
<!-- |    This document was autogenerated by xacro from robot.xacro                    | -->
<!-- |    EDITING THIS FILE BY HAND IS NOT RECOMMENDED                                 | -->
<!-- =================================================================================== -->
<robot name="name">
  <link name="base_link">
    <inertia>
      <mass value="10"/>
      <origin rpy="0 0 0" xyz="0 0 0"/>
      <inertia ixx="0.000526666666667" ixy="0" ixz="0" iyy="0.000526666666667" iyz="0" izz="0.001"/>
    </inertia>
  </link>
  <joint name="joint_1" type="revolute">
    <parent link="base_link"/>
    <child link="link_1"/>
    <origin rpy="0 0 0" xyz="0 0 0.25"/>
    <axis xyz="1 0 0"/>
    <limit effort="500" lower="-1.5707963267948966" upper="1.5707963267948966" velocity="100"/>
  </joint>
  <link name="link_1">
    <inertia>
      <mass value="2.5"/>
      <origin rpy="0 0 0" xyz="0 0 0"/>
      <inertia ixx="0.000526666666667" ixy="0" ixz="0" iyy="0.000526666666667" iyz="0" izz="0.001"/>
    </inertia>
    <origin rpy="0 0 0" xyz="0 0 -0.375"/>
  </link>
  <joint name="joint_2" type="revolute">
    <parent link="link_1"/>
    <child link="link_2"/>
    <origin rpy="0 0 0" xyz="0 0 0.375"/>
    <axis xyz="1 0 0"/>
    <limit effort="500" lower="-1.5707963267948966" upper="1.5707963267948966" velocity="100"/>
  </joint>
  <link name="link_2">
    <inertia>
      <mass value="2.5"/>
      <origin rpy="0 0 0" xyz="0 0 0"/>
      <inertia ixx="0.000526666666667" ixy="0" ixz="0" iyy="0.000526666666667" iyz="0" izz="0.001"/>
    </inertia>
    <origin rpy="0 0 0" xyz="0 0 -0.375"/>
  </link>
</robot>
