<?xml version="1.0" ?>
<!-- =================================================================================== -->
<!-- |    This document was autogenerated by xacro from main.xacro                     | -->
<!-- |    EDITING THIS FILE BY HAND IS NOT RECOMMENDED                                 | -->
<!-- =================================================================================== -->
<robot name="robot">
    <!--
<xacro:macro name="" params="">

</xacro:macro>
-->
    <!-- Inertia Matrix of the cilinder -->
    <!-- link of the wheel of the chassis (use this alongside with joint_wheel) -->
    <!-- joint of the wheel on the chassis -->
    <!--
<xacro:property name="" value=""/>
-->
    <material name="black">
        <color rgba="0.0 0.0 0.0 1.0" />
    </material>
    <material name="blue">
        <color rgba="0.203125 0.23828125 0.28515625 1.0" />
    </material>
    <material name="green">
        <color rgba="0.0 0.8 0.0 1.0" />
    </material>
    <material name="grey">
        <color rgba="0.2 0.2 0.2 1.0" />
    </material>
    <material name="orange">
        <color rgba="1.0 0.423529411765 0.0392156862745 1.0" />
    </material>
    <material name="brown">
        <color rgba="0.870588235294 0.811764705882 0.764705882353 1.0" />
    </material>
    <material name="red">
        <color rgba="0.80078125 0.12890625 0.1328125 1.0" />
    </material>
    <material name="white">
        <color rgba="1.0 1.0 1.0 1.0" />
    </material>
    <!-- Gazebo materials -->
    <gazebo reference="base_link">
        <material>Gazebo/Orange</material>
        <plugin name="gazebo_ros_control">
            <robotNamespace>/</robotNamespace>
        </plugin>
    </gazebo>
    <gazebo reference="link_left_wheel">
        <material>Gazebo/Blue</material>
    </gazebo>
    <gazebo reference="link_right_wheel">
        <material>Gazebo/Blue</material>
    </gazebo>
    <gazebo reference="arm_base_link">
        <material>Gazebo/Red</material>
    </gazebo>
    <gazebo reference="arm_link_01">
        <material>Gazebo/Red</material>
    </gazebo>
    <gazebo reference="arm_link_02">
        <material>Gazebo/Red</material>
    </gazebo>
    <gazebo reference="arm_link_03">
        <material>Gazebo/Red</material>
    </gazebo>
    <gazebo reference="arm_link_03">
        <material>Gazebo/Red</material>
    </gazebo>
    <gazebo reference="arm_link_04">
        <material>Gazebo/Red</material>
    </gazebo>
    <gazebo reference="right_grip_link">
        <material>Gazebo/White</material>
    </gazebo>
    <gazebo reference="left_grip_link">
        <material>Gazebo/White</material>
    </gazebo>
    <!-- Gazebo materials -->
    <!-- The ft_sensor plugin -->
    <gazebo reference="arm_joint_02">
        <provideFeedback>true</provideFeedback>
    </gazebo>
    <gazebo>
        <plugin filename="libgazebo_ros_ft_sensor.so" name="ft_sensor">
            <updateRate>100.0</updateRate>
            <topicName>ft_sensor_topic</topicName>
            <jointName>arm_joint_02</jointName>
        </plugin>
    </gazebo>
    <!-- The ft_sensor plugin -->
    <!-- differential drive controller plugin -->
    <gazebo>
        <plugin filename="libgazebo_ros_diff_drive.so" name="differential_drive_controller">
            <legacyMode>true</legacyMode>
            <rosDebugLevel>na</rosDebugLevel>
            <alwaysOn>true</alwaysOn>
            <updateRate>20</updateRate>
            <robotBaseFrame>root_link</robotBaseFrame>
            <leftJoint>joint_left_wheel</leftJoint>
            <rightJoint>joint_right_wheel</rightJoint>
            <wheelSeparation>0.3</wheelSeparation>
            <wheelDiameter>0.2</wheelDiameter>
            <torque>0.1</torque>
            <wheelAcceleration>0</wheelAcceleration>
            <wheelTorque>5</wheelTorque>
            <commandTopic>cmd_vel</commandTopic>
            <odometryTopic>odom</odometryTopic>
            <odometryFrame>odom</odometryFrame>
            <odometrySource>1</odometrySource>
            <publishWheelJointState>true</publishWheelJointState>
            <publishTf>1</publishTf>
            <publishOdomTf>true</publishOdomTf>
            <publishWheelTF>false</publishWheelTF>
        </plugin>
    </gazebo>
    <!-- differential drive controller plugin -->
    <!-- laser sensor plugin -->
    <gazebo reference="laser">
        <sensor name="head_hokuyo_sensor" type="ray">
            <pose>0 0 0 0 0 0</pose>
            <visualize>false</visualize>
            <update_rate>20</update_rate>
            <ray>
                <scan>
                    <horizontal>
                        <samples>720</samples>
                        <resolution>1</resolution>
                        <min_angle>-1.570796</min_angle>
                        <max_angle>1.570796</max_angle>
                    </horizontal>
                </scan>
                <range>
                    <min>0.10</min>
                    <max>10.0</max>
                    <resolution>0.01</resolution>
                </range>
                <noise>
                    <type>gaussian</type>
                    <mean>0.0</mean>
                    <stddev>0.01</stddev>
                </noise>
            </ray>
            <plugin filename="libgazebo_ros_laser.so" name="gazebo_ros_head_hokuyo_controller">
                <topicName>arm_robot/laser/scan</topicName>
                <frameName>laser</frameName>
            </plugin>
        </sensor>
    </gazebo>
    <!-- laser sensor plugin -->
    <!-- ros control plugin -->
    <gazebo>
        <plugin filename="libgazebo_ros_control.so" name="gazebo_ros_control">
            <robotNamespace>arm_robot</robotNamespace>
            <robotSimType>gazebo_ros_control/DefaultRobotHWSim</robotSimType>
            <legacyModeNS>true</legacyModeNS>
        </plugin>
    </gazebo>
    <!-- ros control plugin -->
    <!-- dummy link (model root) -->
    <!-- see this post : 
	https://answers.ros.org/question/192817/error-msg-the-root-link_base-has-an-inertia-specified-in-the-urdf-but-kdl/
	-->
    <link name="root_link">
        <origin rpy="0 0 0" xyz="0 0 0" />
    </link>
    <!-- chassis and front caster wheel -->
    <link name="base_link">
        <pose>0 0 0.1 0 0 0</pose>
        <inertial>
            <mass value="5" />
            <origin rpy="0 0 0" xyz="0 0 0" />
            <inertia ixx="0.0395416666667" ixy="0" ixz="0" iyy="0.106208333333" iyz="0" izz="0.106208333333" />
        </inertial>
        <!-- collision and visual chassis -->
        <collision name="collision_chassis">
            <geometry>
                <box size="0.5 0.3 0.07" />
            </geometry>
        </collision>
        <visual>
            <origin rpy="0 0 0" xyz="0 0 0" />
            <geometry>
                <box size="0.5 0.3 0.07" />
            </geometry>
            <material name="blue" />
        </visual>
        <!-- collision and visual chassis -->
        <!-- collision, physics and visual of the front caster wheel -->
        <collision name="caster_front_collision">
            <origin rpy=" 0 0 0" xyz="0.35 0 -0.05" />
            <geometry>
                <sphere radius="0.05" />
            </geometry>
            <surface>
                <friction>
                    <ode>
                        <mu>0</mu>
                        <mu2>0</mu2>
                        <slip1>1.0</slip1>
                        <slip2>1.0</slip2>
                    </ode>
                </friction>
            </surface>
        </collision>
        <visual name="caster_front_visual">
            <origin rpy=" 0 0 0" xyz="0.2 0 -0.05" />
            <geometry>
                <sphere radius="0.05" />
            </geometry>
        </visual>
        <!-- collision, physics and visual of the front caster wheel -->
    </link>
    <!-- chassis and front caster wheel -->
    <!-- place for laser sensors -->
    <joint name="joint_laser" type="fixed">
        <parent link="base_link" />
        <child link="laser" />
        <origin rpy="0 0 0" xyz="0.15 0 0.05" />
    </joint>
    <link name="laser">
        <inertial>
            <origin rpy="0 0 0" xyz="0 0 0" />
            <mass value="1" />
            <inertia ixx="0.0014583333333333334" ixy="0" ixz="0" iyy="0.0014583333333333334" iyz="0" izz="0.0012500000000000002" />
        </inertial>
        <visual>
            <origin rpy="0 0 0" xyz="0 0 0" />
            <geometry>
                <cylinder length="0.1" radius="0.05" />
            </geometry>
            <material name="white" />
        </visual>
        <collision>
            <origin rpy="0 0 0" xyz="0 0 0" />
            <geometry>
                <cylinder length="0.1" radius="0.05" />
            </geometry>
        </collision>
    </link>
    <!-- place for laser sensors -->
    <link name="link_right_wheel">
        <origin rpy="0 0 0" xyz="0 0 0" />
        <inertial>
            <mass value="0.2" />
            <origin rpy="0 1.5707 1.5707" xyz="0 0 0" />
            <inertia ixx="0.000526666666667" ixy="0" ixz="0" iyy="0.000526666666667" iyz="0" izz="0.001" />
        </inertial>
        <collision name="link_right_wheel_collision">
            <origin rpy="0 1.5707 1.5707" xyz="0 0 0" />
            <geometry>
                <cylinder length="0.04" radius="0.1" />
            </geometry>
        </collision>
        <visual name="link_right_wheel_visual">
            <origin rpy="0 1.5707 1.5707" xyz="0 0 0" />
            <geometry>
                <cylinder length="0.04" radius="0.1" />
            </geometry>
        </visual>
    </link>
    <joint name="joint_right_wheel" type="continuous">
        <parent link="base_link" />
        <child link="link_right_wheel" />
        <origin rpy="0 0 0" xyz="-0.05 0.15 0" />
        <axis rpy="0 0 0" xyz="0 1 0" />
        <limit effort="10000" velocity="1000" />
        <joint_properties damping="1.0" friction="1.0" />
    </joint>
    <link name="link_left_wheel">
        <origin rpy="0 0 0" xyz="0 0 0" />
        <inertial>
            <mass value="0.2" />
            <origin rpy="0 1.5707 1.5707" xyz="0 0 0" />
            <inertia ixx="0.000526666666667" ixy="0" ixz="0" iyy="0.000526666666667" iyz="0" izz="0.001" />
        </inertial>
        <collision name="link_right_wheel_collision">
            <origin rpy="0 1.5707 1.5707" xyz="0 0 0" />
            <geometry>
                <cylinder length="0.04" radius="0.1" />
            </geometry>
        </collision>
        <visual name="link_left_wheel_visual">
            <origin rpy="0 1.5707 1.5707" xyz="0 0 0" />
            <geometry>
                <cylinder length="0.04" radius="0.1" />
            </geometry>
        </visual>
    </link>
    <joint name="joint_left_wheel" type="continuous">
        <parent link="base_link" />
        <child link="link_left_wheel" />
        <origin rpy="0 0 0" xyz="-0.05 -0.15 0" />
        <axis rpy="0 0 0" xyz="0 1 0" />
        <limit effort="10000" velocity="1000" />
        <joint_properties damping="1.0" friction="1.0" />
    </joint>
    <!-- Wheels -->
    <joint name="root_joint" type="fixed">
        <parent link="root_link" />
        <child link="base_link" />
        <origin rpy="0 0 0" xyz="0 0 0" />
    </joint>
    <!-- base link of the manipulator -->
    <link name="arm_base_link">
        <origin rpy="0 0 0" xyz="0 0 0" />
        <inertial>
            <mass value="0.1" />
            <origin rpy="0 0 0" xyz="0 0 0" />
            <inertia ixx="0.0000416666667" ixy="0" ixz="0" iyy="0.0000416666667" iyz="0" izz="0.0000416666667" />
        </inertial>
        <collision>
            <origin rpy="0 0 0" xyz="0 0 0" />
            <geometry>
                <box size="0.1 0.1 0.1" />
            </geometry>
        </collision>
        <visual>
            <origin rpy="0 0 0" xyz="0 0 0" />
            <geometry>
                <box size="0.1 0.1 0.1" />
            </geometry>
            <material name="red" />
        </visual>
    </link>
    <!-- base link of the manipulator -->
    <!-- first link of the manipulator -->
    <joint name="arm_joint_01" type="revolute">
        <parent link="arm_base_link" />
        <child link="arm_link_01" />
        <origin rpy="0 0 0" xyz="0 0 0.05" />
        <axis xyz="0 0 1" />
        <limit effort="1000.0" lower="-3.12" upper="3.139" velocity="5" />
    </joint>
    <link name="arm_link_01">
        <origin rpy="0 0 0" xyz="0 0 0" />
        <inertial>
            <origin rpy="0 0 0" xyz="0 0 0.1" />
            <mass value="0.025" />
            <inertia ixx="9.333333333333334e-05" ixy="0" ixz="0" iyy="9.333333333333334e-05" iyz="0" izz="2e-05" />
        </inertial>
        <collision>
            <origin rpy="0 0 0" xyz="0 0 0.1" />
            <geometry>
                <cylinder length="0.2" radius="0.04" />
            </geometry>
        </collision>
        <visual>
            <origin rpy="0 0 0" xyz="0 0 0.1" />
            <geometry>
                <cylinder length="0.2" radius="0.04" />
            </geometry>
            <material name="red" />
        </visual>
    </link>
    <!-- first link of the manipulator -->
    <!-- second link of the manipulator -->
    <joint name="arm_joint_02" type="revolute">
        <parent link="arm_link_01" />
        <child link="arm_link_02" />
        <origin rpy="0 0 0" xyz="0 0 0.2" />
        <axis xyz="0 1 0" />
        <limit effort="1000.0" lower="-1.8" upper="1.8" velocity="5" />
    </joint>
    <link name="arm_link_02">
        <origin rpy="0 0 0" xyz="0 0 0" />
        <inertial>
            <origin rpy="0 0 0" xyz="0 0 0.1" />
            <mass value="0.025" />
            <inertia ixx="9.333333333333334e-05" ixy="0" ixz="0" iyy="9.333333333333334e-05" iyz="0" izz="2e-05" />
        </inertial>
        <collision>
            <origin rpy="0 0 0" xyz="0 0 0.1" />
            <geometry>
                <cylinder length="0.2" radius="0.04" />
            </geometry>
        </collision>
        <visual>
            <origin rpy="0 0 0" xyz="0 0 0.1" />
            <geometry>
                <cylinder length="0.2" radius="0.04" />
            </geometry>
            <material name="red" />
        </visual>
    </link>
    <!-- second link of the manipulator -->
    <!-- third link of the manipulator -->
    <joint name="arm_joint_03" type="revolute">
        <parent link="arm_link_02" />
        <child link="arm_link_03" />
        <origin rpy="0 0 0" xyz="0 0 0.2" />
        <axis xyz="0 1 0" />
        <limit effort="1000.0" lower="-1.8" upper="1.8" velocity="5" />
    </joint>
    <link name="arm_link_03">
        <origin rpy="0 0 0" xyz="0 0 0" />
        <inertial>
            <origin rpy="0 0 0" xyz="0 0 0.1" />
            <mass value="0.025" />
            <inertia ixx="9.333333333333334e-05" ixy="0" ixz="0" iyy="9.333333333333334e-05" iyz="0" izz="2e-05" />
        </inertial>
        <collision>
            <origin rpy="0 0 0" xyz="0 0 0.1" />
            <geometry>
                <cylinder length="0.2" radius="0.04" />
            </geometry>
        </collision>
        <visual>
            <origin rpy="0 0 0" xyz="0 0 0.1" />
            <geometry>
                <cylinder length="0.2" radius="0.04" />
            </geometry>
            <material name="red" />
        </visual>
    </link>
    <!-- third link of the manipulator -->
    <!-- last link of the manipulator, base gripper -->
    <joint name="arm_joint_04" type="revolute">
        <parent link="arm_link_03" />
        <child link="arm_link_04" />
        <origin rpy="0 0 0" xyz="0 0 0.2" />
        <axis xyz="0 1 0" />
        <limit effort="10000.0" lower="-1.8" upper="1.8" velocity="5" />
    </joint>
    <link name="arm_link_04">
        <origin rpy="0 0 0" xyz="0 0 0" />
        <inertial>
            <origin rpy="0 0 0" xyz="0 0 0.04" />
            <mass value="0.025" />
            <inertia ixx="0.000010279" ixy="0" ixz="0" iyy="0.000010279" iyz="0" izz="0.000007225" />
        </inertial>
        <collision>
            <origin rpy="0 0 0" xyz="0 0 0.04" />
            <geometry>
                <box size="0.034 0.2 0.08" />
            </geometry>
        </collision>
        <visual>
            <origin rpy="0 0 0" xyz="0 0 0.04" />
            <geometry>
                <box size="0.034 0.2 0.08" />
            </geometry>
            <material name="red" />
        </visual>
    </link>
    --&gt;
    <!-- last link of the manipulator, base gripper -->
    <!-- right gripper -->
    <joint name="right_grip_joint" type="prismatic">
        <parent link="arm_link_04" />
        <child link="right_grip_link" />
        <origin rpy="0 0 0" xyz="0.045 0.05 0.04" />
        <axis xyz="0 1 0" />
        <limit effort="1000.0" lower="-0.04" upper="0.035" velocity="6.5" />
    </joint>
    <link name="right_grip_link">
        <origin rpy="0 0 0" xyz="0 0 0" />
        <inertial>
            <mass value="0.01" />
            <origin rpy="0 0 0" xyz="0 0 0" />
            <inertia ixx="0.000010279" ixy="0" ixz="0" iyy="0.000010279" iyz="0" izz="0.000007225" />
        </inertial>
        <collision>
            <origin rpy="0 0 0" xyz="0 0 0" />
            <geometry>
                <box size="0.06 0.02 0.08" />
            </geometry>
        </collision>
        <visual>
            <origin rpy="0 0 0" xyz="0 0 0" />
            <geometry>
                <box size="0.06 0.02 0.08" />
            </geometry>
            <material name="white" />
        </visual>
    </link>
    <!-- right gripper -->
    <!-- left gripper -->
    <joint name="left_grip_joint" type="prismatic">
        <parent link="arm_link_04" />
        <child link="left_grip_link" />
        <origin rpy="0 0 0" xyz="0.045 -0.05 0.04" />
        <axis xyz="0 1 0" />
        <limit effort="1000.0" lower="-0.035" upper="0.04" velocity="6.5" />
    </joint>
    <link name="left_grip_link">
        <origin rpy="0 0 0" xyz="0 0 0" />
        <inertial>
            <mass value="0.01" />
            <origin rpy="0 0 0" xyz="0 0 0" />
            <inertia ixx="0.000010279" ixy="0" ixz="0" iyy="0.000010279" iyz="0" izz="0.000007225" />
        </inertial>
        <collision>
            <origin rpy="0 0 0" xyz="0 0 0" />
            <geometry>
                <box size="0.06 0.02 0.08" />
            </geometry>
        </collision>
        <visual>
            <origin rpy="0 0 0" xyz="0 0 0" />
            <geometry>
                <box size="0.06 0.02 0.08" />
            </geometry>
            <material name="white" />
        </visual>
    </link>
    <!-- left gripper -->
    <joint name="arm_base_to_base" type="fixed">
        <parent link="base_link" />
        <child link="arm_base_link" />
        <!-- origin : 0.5*(chassis height) + 0.5*(arm base link height) -->
        <origin rpy="0 0 0" xyz="0 0 0.085" />
    </joint>
    <transmission name="arm_joint_01_trans">
        <type>transmission_interface/SimpleTransmission</type>
        <joint name="arm_joint_01">
            <hardwareInterface>hardware_interface/EffortJointInterface</hardwareInterface>
        </joint>
        <actuator name="motor1">
            <hardwareInterface>hardware_interface/EffortJointInterface</hardwareInterface>
            <mechanicalInterface>1</mechanicalInterface>
            <mechanicalReduction>1</mechanicalReduction>
        </actuator>
    </transmission>
    <transmission name="arm_joint_02_trans">
        <type>transmission_interface/SimpleTransmission</type>
        <joint name="arm_joint_02">
            <hardwareInterface>hardware_interface/EffortJointInterface</hardwareInterface>
        </joint>
        <actuator name="motor2">
            <hardwareInterface>hardware_interface/EffortJointInterface</hardwareInterface>
            <mechanicalInterface>1</mechanicalInterface>
            <mechanicalReduction>1</mechanicalReduction>
        </actuator>
    </transmission>
    <transmission name="arm_joint_03_trans">
        <type>transmission_interface/SimpleTransmission</type>
        <joint name="arm_joint_03">
            <hardwareInterface>hardware_interface/EffortJointInterface</hardwareInterface>
        </joint>
        <actuator name="motor3">
            <hardwareInterface>hardware_interface/EffortJointInterface</hardwareInterface>
            <mechanicalInterface>1</mechanicalInterface>
            <mechanicalReduction>1</mechanicalReduction>
        </actuator>
    </transmission>
    <transmission name="arm_joint_04_trans">
        <type>transmission_interface/SimpleTransmission</type>
        <joint name="arm_joint_04">
            <hardwareInterface>hardware_interface/EffortJointInterface</hardwareInterface>
        </joint>
        <actuator name="motor4">
            <hardwareInterface>hardware_interface/EffortJointInterface</hardwareInterface>
            <mechanicalInterface>1</mechanicalInterface>
            <mechanicalReduction>1</mechanicalReduction>
        </actuator>
    </transmission>
    <transmission name="left_grip_trans">
        <type>transmission_interface/SimpleTransmission</type>
        <joint name="left_grip_joint">
            <hardwareInterface>hardware_interface/EffortJointInterface</hardwareInterface>
        </joint>
        <actuator name="motor5">
            <hardwareInterface>hardware_interface/EffortJointInterface</hardwareInterface>
            <mechanicalInterface>1</mechanicalInterface>
            <mechanicalReduction>1</mechanicalReduction>
        </actuator>
    </transmission>
    <transmission name="right_grip_trans">
        <type>transmission_interface/SimpleTransmission</type>
        <joint name="right_grip_joint">
            <hardwareInterface>hardware_interface/EffortJointInterface</hardwareInterface>
        </joint>
        <actuator name="motor6">
            <hardwareInterface>hardware_interface/EffortJointInterface</hardwareInterface>
            <mechanicalInterface>1</mechanicalInterface>
            <mechanicalReduction>1</mechanicalReduction>
        </actuator>
    </transmission>
    <transmission name="trans_joint_right_wheel">
        <type>transmission_interface/SimpleTransmission</type>
        <joint name="joint_right_wheel">
            <hardwareInterface>hardware_interface/EffortJointInterface</hardwareInterface>
        </joint>
        <actuator name="joint_right_wheel_motor">
            <hardwareInterface>hardware_interface/EffortJointInterface</hardwareInterface>
            <mechanicalReduction>1</mechanicalReduction>
        </actuator>
    </transmission>
    <transmission name="trans_joint_left_wheel">
        <type>transmission_interface/SimpleTransmission</type>
        <joint name="joint_left_wheel">
            <hardwareInterface>hardware_interface/EffortJointInterface</hardwareInterface>
        </joint>
        <actuator name="joint_left_wheel_motor">
            <hardwareInterface>hardware_interface/EffortJointInterface</hardwareInterface>
            <mechanicalReduction>1</mechanicalReduction>
        </actuator>
    </transmission>
</robot>

